Workbook

Sheet Annual Summary
A1: WELFARE OFFICER – ANNUAL SUMMARY 2026-27
A3: Factory Name | D3: Welfare Officer
A5: KPI | B5: Apr | C5: May | D5: Jun | E5: Jul | F5: Aug | G5: Sep | H5: Oct | I5: Nov | J5: Dec | K5: Jan | L5: Feb | M5: Mar | N5: Annual Total
A6: Total Workers | B6: =Apr!B15 -> 0 | C6: =May!B15 -> 0 | D6: =Jun!B15 -> 0 | E6: =Jul!B15 -> 0 | F6: =Aug!B15 -> 0 | G6: =Sep!B15 -> 236 | H6: =Oct!B15 -> 0 | I6: =Nov!B15 -> 0 | J6: =Dec!B15 -> 0 | K6: =Jan!B15 -> 0 | L6: =Feb!B15 -> 0 | M6: =Mar!B15 -> 0 | N6: =AVERAGE(B6:M6) -> 19.666667
A7: Welfare Activities | B7: =Apr!B107 -> 0 | C7: =May!B107 -> 0 | D7: =Jun!B107 -> 0 | E7: =Jul!B107 -> 0 | F7: =Aug!B107 -> 0 | G7: =Sep!B108 -> 248 | H7: =Oct!B107 -> 0 | I7: =Nov!B107 -> 0 | J7: =Dec!B107 -> 0 | K7: =Jan!B107 -> 0 | L7: =Feb!B107 -> 0 | M7: =Mar!B107 -> 0 | N7: =SUM(B7:M7) -> 248
A8: Grievances Received | B8: =Apr!B108 -> 0 | C8: =May!B108 -> 0 | D8: =Jun!B108 -> 0 | E8: =Jul!B108 -> 0 | F8: =Aug!B108 -> 0 | G8: =Sep!B109 -> 11 | H8: =Oct!B108 -> 0 | I8: =Nov!B108 -> 0 | J8: =Dec!B108 -> 0 | K8: =Jan!B108 -> 0 | L8: =Feb!B108 -> 0 | M8: =Mar!B108 -> 0 | N8: =SUM(B8:M8) -> 11
A9: Grievances Resolved | B9: =Apr!B109 -> 0 | C9: =May!B109 -> 0 | D9: =Jun!B109 -> 0 | E9: =Jul!B109 -> 0 | F9: =Aug!B109 -> 0 | G9: =Sep!B110 -> 7 | H9: =Oct!B109 -> 0 | I9: =Nov!B109 -> 0 | J9: =Dec!B109 -> 0 | K9: =Jan!B109 -> 0 | L9: =Feb!B109 -> 0 | M9: =Mar!B109 -> 0 | N9: =SUM(B9:M9) -> 7
A10: Accidents | B10: =Apr!B110 -> 0 | C10: =May!B110 -> 0 | D10: =Jun!B110 -> 0 | E10: =Jul!B110 -> 0 | F10: =Aug!B110 -> 0 | G10: =Sep!B111 -> 7 | H10: =Oct!B110 -> 0 | I10: =Nov!B110 -> 0 | J10: =Dec!B110 -> 0 | K10: =Jan!B110 -> 0 | L10: =Feb!B110 -> 0 | M10: =Mar!B110 -> 0 | N10: =SUM(B10:M10) -> 7
A11: Medical Cases | B11: =Apr!B111 -> 0 | C11: =May!B111 -> 0 | D11: =Jun!B111 -> 0 | E11: =Jul!B111 -> 0 | F11: =Aug!B111 -> 0 | G11: =Sep!B112 -> 6 | H11: =Oct!B111 -> 0 | I11: =Nov!B111 -> 0 | J11: =Dec!B111 -> 0 | K11: =Jan!B111 -> 0 | L11: =Feb!B111 -> 0 | M11: =Mar!B111 -> 0 | N11: =SUM(B11:M11) -> 6
A12: Training Sessions | B12: =Apr!B112 -> 0 | C12: =May!B112 -> 0 | D12: =Jun!B112 -> 0 | E12: =Jul!B112 -> 0 | F12: =Aug!B112 -> 0 | G12: =Sep!B113 -> 30 | H12: =Oct!B112 -> 0 | I12: =Nov!B112 -> 0 | J12: =Dec!B112 -> 0 | K12: =Jan!B112 -> 0 | L12: =Feb!B112 -> 0 | M12: =Mar!B112 -> 0 | N12: =SUM(B12:M12) -> 30
A13: Welfare Inspections | B13: =Apr!B113 -> 6 | C13: =May!B113 -> 6 | D13: =Jun!B113 -> 6 | E13: =Jul!B113 -> 6 | F13: =Aug!B113 -> 6 | G13: =Sep!B114 -> 6 | H13: =Oct!B113 -> 6 | I13: =Nov!B113 -> 6 | J13: =Dec!B113 -> 6 | K13: =Jan!B113 -> 6 | L13: =Feb!B113 -> 6 | M13: =Mar!B113 -> 6 | N13: =SUM(B13:M13) -> 72
A16: ANNUAL MANAGEMENT OBSERVATIONS / KEY ACTIONS
A17: Record major welfare achievements, recurring grievances, accident trends, statutory observations, pending CAPA and management support required.

Sheet Apr
A1: WELFARE OFFICER RETURN – Apr 2026-27
A3: Factory Name | D3: Factory Licence No.
A4: Address | D4: Reporting Period | E4: Apr 2026-27
A5: Welfare Officer | D5: Total Workers | E5: =E15 -> 0
A7: A. MANPOWER STATEMENT
A8: Category | B8: Opening | C8: Joining | D8: Separation | E8: Closing
A9: Permanent Workers | B9: 0 | C9: 0 | D9: 0 | E9: 0
A10: Contract Workers | B10: 0 | C10: 0 | D10: 0 | E10: 0
A11: Temporary Workers | B11: 0 | C11: 0 | D11: 0 | E11: 0
A12: Apprentices/Trainees | B12: 0 | C12: 0 | D12: 0 | E12: 0
A13: Male Workers | B13: 0 | C13: 0 | D13: 0 | E13: 0
A14: Female Workers | B14: 0 | C14: 0 | D14: 0 | E14: 0
A15: TOTAL | B15: =SUM(B9:B14) -> 0 | C15: =SUM(C9:C14) -> 0 | D15: =SUM(D9:D14) -> 0 | E15: =SUM(E9:E14) -> 0
A17: B. WELFARE FACILITIES
A18: Facility | B18: Available (Y/N) | C18: No./Capacity | D18: Condition | E18: Observation | F18: Action Required
A19: Canteen | B19: Yes | D19: Satisfactory
A20: Drinking Water | B20: Yes | D20: Satisfactory
A21: Washing Facility | B21: Yes | D21: Satisfactory
A22: Rest/Shelter Room | B22: Yes | D22: Satisfactory
A23: First-Aid Boxes | B23: Yes | D23: Satisfactory
A24: Medical Facility | B24: Yes | D24: Satisfactory
A25: Ambulance/Transport | B25: Yes | D25: Satisfactory
A26: Toilets | B26: Yes | D26: Satisfactory
A27: Changing Room | B27: Yes | D27: Satisfactory
A28: Creche (if applicable) | B28: Yes | D28: Satisfactory
A30: C. HEALTH & MEDICAL
A31: Particular | B31: Count | C31: Remarks
A32: Medical cases attended | B32: 0
A33: First-aid cases | B33: 0
A34: Hospitalisation cases | B34: 0
A35: Medical examination conducted | B35: 0
A36: Health camps conducted | B36: 0
A37: Occupational health cases | B37: 0
A38: Ambulance cases | B38: 0
A39: ESIC cases | B39: 0
A41: D. ACCIDENT STATEMENT
A42: Particular | B42: No. of Cases | C42: Man-days Lost
A43: Fatal Accident | B43: 0 | C43: 0
A44: Major Accident | B44: 0 | C44: 0
A45: Minor Accident | B45: 0 | C45: 0
...

Sheet May
A1: WELFARE OFFICER RETURN – May 2026-27
A3: Factory Name | D3: Factory Licence No.
A4: Address | D4: Reporting Period | E4: May 2026-27
A5: Welfare Officer | D5: Total Workers | E5: =E15 -> 0
A7: A. MANPOWER STATEMENT
A8: Category | B8: Opening | C8: Joining | D8: Separation | E8: Closing
A9: Permanent Workers | B9: 0 | C9: 0 | D9: 0 | E9: 0
A10: Contract Workers | B10: 0 | C10: 0 | D10: 0 | E10: 0
A11: Temporary Workers | B11: 0 | C11: 0 | D11: 0 | E11: 0
A12: Apprentices/Trainees | B12: 0 | C12: 0 | D12: 0 | E12: 0
A13: Male Workers | B13: 0 | C13: 0 | D13: 0 | E13: 0
A14: Female Workers | B14: 0 | C14: 0 | D14: 0 | E14: 0
A15: TOTAL | B15: =SUM(B9:B14) -> 0 | C15: =SUM(C9:C14) -> 0 | D15: =SUM(D9:D14) -> 0 | E15: =SUM(E9:E14) -> 0
A17: B. WELFARE FACILITIES
A18: Facility | B18: Available (Y/N) | C18: No./Capacity | D18: Condition | E18: Observation | F18: Action Required
A19: Canteen | B19: Yes | D19: Satisfactory
A20: Drinking Water | B20: Yes | D20: Satisfactory
A21: Washing Facility | B21: Yes | D21: Satisfactory
A22: Rest/Shelter Room | B22: Yes | D22: Satisfactory
A23: First-Aid Boxes | B23: Yes | D23: Satisfactory
A24: Medical Facility | B24: Yes | D24: Satisfactory
A25: Ambulance/Transport | B25: Yes | D25: Satisfactory
A26: Toilets | B26: Yes | D26: Satisfactory
A27: Changing Room | B27: Yes | D27: Satisfactory
A28: Creche (if applicable) | B28: Yes | D28: Satisfactory
A30: C. HEALTH & MEDICAL
A31: Particular | B31: Count | C31: Remarks
A32: Medical cases attended | B32: 0
A33: First-aid cases | B33: 0
A34: Hospitalisation cases | B34: 0
A35: Medical examination conducted | B35: 0
A36: Health camps conducted | B36: 0
A37: Occupational health cases | B37: 0
A38: Ambulance cases | B38: 0
A39: ESIC cases | B39: 0
A41: D. ACCIDENT STATEMENT
A42: Particular | B42: No. of Cases | C42: Man-days Lost
A43: Fatal Accident | B43: 0 | C43: 0
A44: Major Accident | B44: 0 | C44: 0
A45: Minor Accident | B45: 0 | C45: 0
...

Sheet Jun
A1: WELFARE OFFICER RETURN – Jun 2026-27
A3: Factory Name | D3: Factory Licence No.
A4: Address | D4: Reporting Period | E4: Jun 2026-27
A5: Welfare Officer | D5: Total Workers | E5: =E15 -> 0
A7: A. MANPOWER STATEMENT
A8: Category | B8: Opening | C8: Joining | D8: Separation | E8: Closing
A9: Permanent Workers | B9: 0 | C9: 0 | D9: 0 | E9: 0
A10: Contract Workers | B10: 0 | C10: 0 | D10: 0 | E10: 0
A11: Temporary Workers | B11: 0 | C11: 0 | D11: 0 | E11: 0
A12: Apprentices/Trainees | B12: 0 | C12: 0 | D12: 0 | E12: 0
A13: Male Workers | B13: 0 | C13: 0 | D13: 0 | E13: 0
A14: Female Workers | B14: 0 | C14: 0 | D14: 0 | E14: 0
A15: TOTAL | B15: =SUM(B9:B14) -> 0 | C15: =SUM(C9:C14) -> 0 | D15: =SUM(D9:D14) -> 0 | E15: =SUM(E9:E14) -> 0
A17: B. WELFARE FACILITIES
A18: Facility | B18: Available (Y/N) | C18: No./Capacity | D18: Condition | E18: Observation | F18: Action Required
A19: Canteen | B19: Yes | D19: Satisfactory
A20: Drinking Water | B20: Yes | D20: Satisfactory
A21: Washing Facility | B21: Yes | D21: Satisfactory
A22: Rest/Shelter Room | B22: Yes | D22: Satisfactory
A23: First-Aid Boxes | B23: Yes | D23: Satisfactory
A24: Medical Facility | B24: Yes | D24: Satisfactory
A25: Ambulance/Transport | B25: Yes | D25: Satisfactory
A26: Toilets | B26: Yes | D26: Satisfactory
A27: Changing Room | B27: Yes | D27: Satisfactory
A28: Creche (if applicable) | B28: Yes | D28: Satisfactory
A30: C. HEALTH & MEDICAL
A31: Particular | B31: Count | C31: Remarks
A32: Medical cases attended | B32: 0
A33: First-aid cases | B33: 0
A34: Hospitalisation cases | B34: 0
A35: Medical examination conducted | B35: 0
A36: Health camps conducted | B36: 0
A37: Occupational health cases | B37: 0
A38: Ambulance cases | B38: 0
A39: ESIC cases | B39: 0
A41: D. ACCIDENT STATEMENT
A42: Particular | B42: No. of Cases | C42: Man-days Lost
A43: Fatal Accident | B43: 0 | C43: 0
A44: Major Accident | B44: 0 | C44: 0
A45: Minor Accident | B45: 0 | C45: 0
...

Sheet Jul
A1: WELFARE OFFICER RETURN – Jul 2026-27
A3: Factory Name | D3: Factory Licence No.
A4: Address | D4: Reporting Period | E4: Jul 2026-27
A5: Welfare Officer | D5: Total Workers | E5: =E15 -> 0
A7: A. MANPOWER STATEMENT
A8: Category | B8: Opening | C8: Joining | D8: Separation | E8: Closing
A9: Permanent Workers | B9: 0 | C9: 0 | D9: 0 | E9: 0
A10: Contract Workers | B10: 0 | C10: 0 | D10: 0 | E10: 0
A11: Temporary Workers | B11: 0 | C11: 0 | D11: 0 | E11: 0
A12: Apprentices/Trainees | B12: 0 | C12: 0 | D12: 0 | E12: 0
A13: Male Workers | B13: 0 | C13: 0 | D13: 0 | E13: 0
A14: Female Workers | B14: 0 | C14: 0 | D14: 0 | E14: 0
A15: TOTAL | B15: =SUM(B9:B14) -> 0 | C15: =SUM(C9:C14) -> 0 | D15: =SUM(D9:D14) -> 0 | E15: =SUM(E9:E14) -> 0
A17: B. WELFARE FACILITIES
A18: Facility | B18: Available (Y/N) | C18: No./Capacity | D18: Condition | E18: Observation | F18: Action Required
A19: Canteen | B19: Yes | D19: Satisfactory
A20: Drinking Water | B20: Yes | D20: Satisfactory
A21: Washing Facility | B21: Yes | D21: Satisfactory
A22: Rest/Shelter Room | B22: Yes | D22: Satisfactory
A23: First-Aid Boxes | B23: Yes | D23: Satisfactory
A24: Medical Facility | B24: Yes | D24: Satisfactory
A25: Ambulance/Transport | B25: Yes | D25: Satisfactory
A26: Toilets | B26: Yes | D26: Satisfactory
A27: Changing Room | B27: Yes | D27: Satisfactory
A28: Creche (if applicable) | B28: Yes | D28: Satisfactory
A30: C. HEALTH & MEDICAL
A31: Particular | B31: Count | C31: Remarks
A32: Medical cases attended | B32: 0
A33: First-aid cases | B33: 0
A34: Hospitalisation cases | B34: 0
A35: Medical examination conducted | B35: 0
A36: Health camps conducted | B36: 0
A37: Occupational health cases | B37: 0
A38: Ambulance cases | B38: 0
A39: ESIC cases | B39: 0
A41: D. ACCIDENT STATEMENT
A42: Particular | B42: No. of Cases | C42: Man-days Lost
A43: Fatal Accident | B43: 0 | C43: 0
A44: Major Accident | B44: 0 | C44: 0
A45: Minor Accident | B45: 0 | C45: 0
...

Sheet Aug
A1: WELFARE OFFICER RETURN – Aug 2026-27
A3: Factory Name | D3: Factory Licence No.
A4: Address | D4: Reporting Period | E4: Aug 2026-27
A5: Welfare Officer | D5: Total Workers | E5: =E15 -> 0
A7: A. MANPOWER STATEMENT
A8: Category | B8: Opening | C8: Joining | D8: Separation | E8: Closing
A9: Permanent Workers | B9: 0 | C9: 0 | D9: 0 | E9: 0
A10: Contract Workers | B10: 0 | C10: 0 | D10: 0 | E10: 0
A11: Temporary Workers | B11: 0 | C11: 0 | D11: 0 | E11: 0
A12: Apprentices/Trainees | B12: 0 | C12: 0 | D12: 0 | E12: 0
A13: Male Workers | B13: 0 | C13: 0 | D13: 0 | E13: 0
A14: Female Workers | B14: 0 | C14: 0 | D14: 0 | E14: 0
A15: TOTAL | B15: =SUM(B9:B14) -> 0 | C15: =SUM(C9:C14) -> 0 | D15: =SUM(D9:D14) -> 0 | E15: =SUM(E9:E14) -> 0
A17: B. WELFARE FACILITIES
A18: Facility | B18: Available (Y/N) | C18: No./Capacity | D18: Condition | E18: Observation | F18: Action Required
A19: Canteen | B19: Yes | D19: Satisfactory
A20: Drinking Water | B20: Yes | D20: Satisfactory
A21: Washing Facility | B21: Yes | D21: Satisfactory
A22: Rest/Shelter Room | B22: Yes | D22: Satisfactory
A23: First-Aid Boxes | B23: Yes | D23: Satisfactory
A24: Medical Facility | B24: Yes | D24: Satisfactory
A25: Ambulance/Transport | B25: Yes | D25: Satisfactory
A26: Toilets | B26: Yes | D26: Satisfactory
A27: Changing Room | B27: Yes | D27: Satisfactory
A28: Creche (if applicable) | B28: Yes | D28: Satisfactory
A30: C. HEALTH & MEDICAL
A31: Particular | B31: Count | C31: Remarks
A32: Medical cases attended | B32: 0
A33: First-aid cases | B33: 0
A34: Hospitalisation cases | B34: 0
A35: Medical examination conducted | B35: 0
A36: Health camps conducted | B36: 0
A37: Occupational health cases | B37: 0
A38: Ambulance cases | B38: 0
A39: ESIC cases | B39: 0
A41: D. ACCIDENT STATEMENT
A42: Particular | B42: No. of Cases | C42: Man-days Lost
A43: Fatal Accident | B43: 0 | C43: 0
A44: Major Accident | B44: 0 | C44: 0
A45: Minor Accident | B45: 0 | C45: 0
...

Sheet Sep
A1: WELFARE OFFICER RETURN – Sep 2026-27
A3: Factory Name | B3: Salasar Techno Engineering Ltd. | D3: Factory Licence No.
A4: Address | B4: Khasra No. 686/6 Village-Khera, Pilkhuwa, Hapur | D4: Reporting Period | E4: Sep 2026-27
A5: Welfare Officer | B5: Vinod Meghwal | D5: Total Workers | E5: 700
A7: A. MANPOWER STATEMENT
A8: Category | B8: Opening | C8: Joining | D8: Separation | E8: Closing
A9: Permanent Workers | B9: 75 | C9: 3 | D9: 1 | E9: =SUM(B9+C9-D9) -> 77 | F9: =D9/AVERAGE(B9,E9) -> 0.013157895
A10: Contract Workers | B10: 35 | C10: 5 | D10: 2 | E10: =SUM(B10+C10-D10) -> 38 | F10: =D10/AVERAGE(B10,E10) -> 0.054794521
A11: Temporary Workers | B11: 5 | C11: 1 | D11: 1 | E11: =SUM(B11+C11-D11) -> 5 | F11: =D11/AVERAGE(B11,E11) -> 0.2
A12: Apprentices/Trainees | B12: 3 | C12: 2 | D12: 1 | E12: =SUM(B12+C12-D12) -> 4 | F12: =D12/AVERAGE(B12,E12) -> 0.28571429
A13: Male Workers | B13: 98 | C13: 8 | D13: 4 | E13: =SUM(B13+C13-D13) -> 102 | F13: =D13/AVERAGE(B13,E13) -> 0.04
A14: Female Workers | B14: 20 | C14: 3 | D14: 1 | E14: =SUM(B14+C14-D14) -> 22 | F14: =D14/AVERAGE(B14,E14) -> 0.047619048
A15: TOTAL | B15: =SUM(B9:B14) -> 236 | C15: =SUM(C9:C14) -> 22 | D15: =SUM(D9:D14) -> 10 | E15: =SUM(E9:E14) -> 248
A17: B. WELFARE FACILITIES
A18: Facility | B18: Available (Y/N) | C18: No./Capacity | D18: Condition | E18: Observation | F18: Action Required
A19: Canteen | B19: Yes | C19: 120 Persons | D19: Satisfactory | E19: Clean and hygienic | F19: Continue regular inspection
A20: Drinking Water | B20: Yes | C20: 6 Points | D20: Satisfactory | E20: Potable water available | F20: Periodic water testing
A21: Washing Facility | B21: Yes | C21: 8 Points | D21: Satisfactory | E21: Adequate and clean | F21: Maintain cleanliness
A22: Rest/Shelter Room | B22: Yes | C22: 20 Person | D22: Satisfactory | E22: Adequately maintained | F22: Regular housekeeping
A23: First-Aid Boxes | B23: Yes | C23: 6 boxes | D23: Satisfactory | E23: Stock available | F23: Check expiry dates monthly
A24: Medical Facility | B24: Yes | C24: 1 room | D24: Satisfactory | E24: Basic medical support available | F24: Maintain medical supplies
A25: Ambulance/Transport | B25: Yes | C25: 1 Vehicle | D25: Satisfactory | E25: Available when required | F25: Periodic vehicle inspection
A26: Toilets | B26: Yes | C26: 18 | D26: Satisfactory | E26: Clean and functional | F26: Regular cleaning
A27: Changing Room | B27: Yes | C27: 2 Rooms | D27: Satisfactory | E27: Adequate facilities | F27: Maintain housekeeping
A28: Creche (if applicable) | B28: Yes | C28: 0 Children | D28: Satisfactory | E28: Facility available | F28: Review attendance periodically
A30: C. HEALTH & MEDICAL
A31: Particular | B31: Count | C31: Remarks
A32: Medical cases attended | B32: 8 | C32: Minor illness and routine medical assistance
A33: First-aid cases | B33: 5 | C33: Minor cuts, bruises and minor injuries
A34: Hospitalisation cases | B34: 1 | C34: Referred for further medical treatment
A35: Medical examination conducted | B35: 12 | C35: Periodic medical examination
A36: Health camps conducted | B36: 1 | C36: General health check-up camp
A37: Occupational health cases | B37: 0 | C37: No occupational disease reported
A38: Ambulance cases | B38: 1 | C38: Hospital referral
A39: ESIC cases | B39: 2 | C39: Cases referred through ESIC
A41: D. ACCIDENT STATEMENT
A42: Particular | B42: No. of Cases | C42: Man-days Lost
A43: Fatal Accident | B43: 0 | C43: 0
A44: Major Accident | B44: 0 | C44: 0
A45: Minor Accident | B45: 2 | C45: 3
...

Sheet Oct
A1: WELFARE OFFICER RETURN – Oct 2026-27
A3: Factory Name | D3: Factory Licence No.
A4: Address | D4: Reporting Period | E4: Oct 2026-27
A5: Welfare Officer | D5: Total Workers | E5: =E15 -> 0
A7: A. MANPOWER STATEMENT
A8: Category | B8: Opening | C8: Joining | D8: Separation | E8: Closing
A9: Permanent Workers | B9: 0 | C9: 0 | D9: 0 | E9: 0
A10: Contract Workers | B10: 0 | C10: 0 | D10: 0 | E10: 0
A11: Temporary Workers | B11: 0 | C11: 0 | D11: 0 | E11: 0
A12: Apprentices/Trainees | B12: 0 | C12: 0 | D12: 0 | E12: 0
A13: Male Workers | B13: 0 | C13: 0 | D13: 0 | E13: 0
A14: Female Workers | B14: 0 | C14: 0 | D14: 0 | E14: 0
A15: TOTAL | B15: =SUM(B9:B14) -> 0 | C15: =SUM(C9:C14) -> 0 | D15: =SUM(D9:D14) -> 0 | E15: =SUM(E9:E14) -> 0
A17: B. WELFARE FACILITIES
A18: Facility | B18: Available (Y/N) | C18: No./Capacity | D18: Condition | E18: Observation | F18: Action Required
A19: Canteen | B19: Yes | D19: Satisfactory
A20: Drinking Water | B20: Yes | D20: Satisfactory
A21: Washing Facility | B21: Yes | D21: Satisfactory
A22: Rest/Shelter Room | B22: Yes | D22: Satisfactory
A23: First-Aid Boxes | B23: Yes | D23: Satisfactory
A24: Medical Facility | B24: Yes | D24: Satisfactory
A25: Ambulance/Transport | B25: Yes | D25: Satisfactory
A26: Toilets | B26: Yes | D26: Satisfactory
A27: Changing Room | B27: Yes | D27: Satisfactory
A28: Creche (if applicable) | B28: Yes | D28: Satisfactory
A30: C. HEALTH & MEDICAL
A31: Particular | B31: Count | C31: Remarks
A32: Medical cases attended | B32: 0
A33: First-aid cases | B33: 0
A34: Hospitalisation cases | B34: 0
A35: Medical examination conducted | B35: 0
A36: Health camps conducted | B36: 0
A37: Occupational health cases | B37: 0
A38: Ambulance cases | B38: 0
A39: ESIC cases | B39: 0
A41: D. ACCIDENT STATEMENT
A42: Particular | B42: No. of Cases | C42: Man-days Lost
A43: Fatal Accident | B43: 0 | C43: 0
A44: Major Accident | B44: 0 | C44: 0
A45: Minor Accident | B45: 0 | C45: 0
...

Sheet Nov
A1: WELFARE OFFICER RETURN – Nov 2026-27
A3: Factory Name | D3: Factory Licence No.
A4: Address | D4: Reporting Period | E4: Nov 2026-27
A5: Welfare Officer | D5: Total Workers | E5: =E15 -> 0
A7: A. MANPOWER STATEMENT
A8: Category | B8: Opening | C8: Joining | D8: Separation | E8: Closing
A9: Permanent Workers | B9: 0 | C9: 0 | D9: 0 | E9: 0
A10: Contract Workers | B10: 0 | C10: 0 | D10: 0 | E10: 0
A11: Temporary Workers | B11: 0 | C11: 0 | D11: 0 | E11: 0
A12: Apprentices/Trainees | B12: 0 | C12: 0 | D12: 0 | E12: 0
A13: Male Workers | B13: 0 | C13: 0 | D13: 0 | E13: 0
A14: Female Workers | B14: 0 | C14: 0 | D14: 0 | E14: 0
A15: TOTAL | B15: =SUM(B9:B14) -> 0 | C15: =SUM(C9:C14) -> 0 | D15: =SUM(D9:D14) -> 0 | E15: =SUM(E9:E14) -> 0
A17: B. WELFARE FACILITIES
A18: Facility | B18: Available (Y/N) | C18: No./Capacity | D18: Condition | E18: Observation | F18: Action Required
A19: Canteen | B19: Yes | D19: Satisfactory
A20: Drinking Water | B20: Yes | D20: Satisfactory
A21: Washing Facility | B21: Yes | D21: Satisfactory
A22: Rest/Shelter Room | B22: Yes | D22: Satisfactory
A23: First-Aid Boxes | B23: Yes | D23: Satisfactory
A24: Medical Facility | B24: Yes | D24: Satisfactory
A25: Ambulance/Transport | B25: Yes | D25: Satisfactory
A26: Toilets | B26: Yes | D26: Satisfactory
A27: Changing Room | B27: Yes | D27: Satisfactory
A28: Creche (if applicable) | B28: Yes | D28: Satisfactory
A30: C. HEALTH & MEDICAL
A31: Particular | B31: Count | C31: Remarks
A32: Medical cases attended | B32: 0
A33: First-aid cases | B33: 0
A34: Hospitalisation cases | B34: 0
A35: Medical examination conducted | B35: 0
A36: Health camps conducted | B36: 0
A37: Occupational health cases | B37: 0
A38: Ambulance cases | B38: 0
A39: ESIC cases | B39: 0
A41: D. ACCIDENT STATEMENT
A42: Particular | B42: No. of Cases | C42: Man-days Lost
A43: Fatal Accident | B43: 0 | C43: 0
A44: Major Accident | B44: 0 | C44: 0
A45: Minor Accident | B45: 0 | C45: 0
...

Sheet Dec
A1: WELFARE OFFICER RETURN – Dec 2026-27
A3: Factory Name | D3: Factory Licence No.
A4: Address | D4: Reporting Period | E4: Dec 2026-27
A5: Welfare Officer | D5: Total Workers | E5: =E15 -> 0
A7: A. MANPOWER STATEMENT
A8: Category | B8: Opening | C8: Joining | D8: Separation | E8: Closing
A9: Permanent Workers | B9: 0 | C9: 0 | D9: 0 | E9: 0
A10: Contract Workers | B10: 0 | C10: 0 | D10: 0 | E10: 0
A11: Temporary Workers | B11: 0 | C11: 0 | D11: 0 | E11: 0
A12: Apprentices/Trainees | B12: 0 | C12: 0 | D12: 0 | E12: 0
A13: Male Workers | B13: 0 | C13: 0 | D13: 0 | E13: 0
A14: Female Workers | B14: 0 | C14: 0 | D14: 0 | E14: 0
A15: TOTAL | B15: =SUM(B9:B14) -> 0 | C15: =SUM(C9:C14) -> 0 | D15: =SUM(D9:D14) -> 0 | E15: =SUM(E9:E14) -> 0
A17: B. WELFARE FACILITIES
A18: Facility | B18: Available (Y/N) | C18: No./Capacity | D18: Condition | E18: Observation | F18: Action Required
A19: Canteen | B19: Yes | D19: Satisfactory
A20: Drinking Water | B20: Yes | D20: Satisfactory
A21: Washing Facility | B21: Yes | D21: Satisfactory
A22: Rest/Shelter Room | B22: Yes | D22: Satisfactory
A23: First-Aid Boxes | B23: Yes | D23: Satisfactory
A24: Medical Facility | B24: Yes | D24: Satisfactory
A25: Ambulance/Transport | B25: Yes | D25: Satisfactory
A26: Toilets | B26: Yes | D26: Satisfactory
A27: Changing Room | B27: Yes | D27: Satisfactory
A28: Creche (if applicable) | B28: Yes | D28: Satisfactory
A30: C. HEALTH & MEDICAL
A31: Particular | B31: Count | C31: Remarks
A32: Medical cases attended | B32: 0
A33: First-aid cases | B33: 0
A34: Hospitalisation cases | B34: 0
A35: Medical examination conducted | B35: 0
A36: Health camps conducted | B36: 0
A37: Occupational health cases | B37: 0
A38: Ambulance cases | B38: 0
A39: ESIC cases | B39: 0
A41: D. ACCIDENT STATEMENT
A42: Particular | B42: No. of Cases | C42: Man-days Lost
A43: Fatal Accident | B43: 0 | C43: 0
A44: Major Accident | B44: 0 | C44: 0
A45: Minor Accident | B45: 0 | C45: 0
...

Sheet Jan
A1: WELFARE OFFICER RETURN – Jan 2026-27
A3: Factory Name | D3: Factory Licence No.
A4: Address | D4: Reporting Period | E4: Jan 2026-27
A5: Welfare Officer | D5: Total Workers | E5: =E15 -> 0
A7: A. MANPOWER STATEMENT
A8: Category | B8: Opening | C8: Joining | D8: Separation | E8: Closing
A9: Permanent Workers | B9: 0 | C9: 0 | D9: 0 | E9: 0
A10: Contract Workers | B10: 0 | C10: 0 | D10: 0 | E10: 0
A11: Temporary Workers | B11: 0 | C11: 0 | D11: 0 | E11: 0
A12: Apprentices/Trainees | B12: 0 | C12: 0 | D12: 0 | E12: 0
A13: Male Workers | B13: 0 | C13: 0 | D13: 0 | E13: 0
A14: Female Workers | B14: 0 | C14: 0 | D14: 0 | E14: 0
A15: TOTAL | B15: =SUM(B9:B14) -> 0 | C15: =SUM(C9:C14) -> 0 | D15: =SUM(D9:D14) -> 0 | E15: =SUM(E9:E14) -> 0
A17: B. WELFARE FACILITIES
A18: Facility | B18: Available (Y/N) | C18: No./Capacity | D18: Condition | E18: Observation | F18: Action Required
A19: Canteen | B19: Yes | D19: Satisfactory
A20: Drinking Water | B20: Yes | D20: Satisfactory
A21: Washing Facility | B21: Yes | D21: Satisfactory
A22: Rest/Shelter Room | B22: Yes | D22: Satisfactory
A23: First-Aid Boxes | B23: Yes | D23: Satisfactory
A24: Medical Facility | B24: Yes | D24: Satisfactory
A25: Ambulance/Transport | B25: Yes | D25: Satisfactory
A26: Toilets | B26: Yes | D26: Satisfactory
A27: Changing Room | B27: Yes | D27: Satisfactory
A28: Creche (if applicable) | B28: Yes | D28: Satisfactory
A30: C. HEALTH & MEDICAL
A31: Particular | B31: Count | C31: Remarks
A32: Medical cases attended | B32: 0
A33: First-aid cases | B33: 0
A34: Hospitalisation cases | B34: 0
A35: Medical examination conducted | B35: 0
A36: Health camps conducted | B36: 0
A37: Occupational health cases | B37: 0
A38: Ambulance cases | B38: 0
A39: ESIC cases | B39: 0
A41: D. ACCIDENT STATEMENT
A42: Particular | B42: No. of Cases | C42: Man-days Lost
A43: Fatal Accident | B43: 0 | C43: 0
A44: Major Accident | B44: 0 | C44: 0
A45: Minor Accident | B45: 0 | C45: 0
...

Sheet Feb
A1: WELFARE OFFICER RETURN – Feb 2026-27
A3: Factory Name | D3: Factory Licence No.
A4: Address | D4: Reporting Period | E4: Feb 2026-27
A5: Welfare Officer | D5: Total Workers | E5: =E15 -> 0
A7: A. MANPOWER STATEMENT
A8: Category | B8: Opening | C8: Joining | D8: Separation | E8: Closing
A9: Permanent Workers | B9: 0 | C9: 0 | D9: 0 | E9: 0
A10: Contract Workers | B10: 0 | C10: 0 | D10: 0 | E10: 0
A11: Temporary Workers | B11: 0 | C11: 0 | D11: 0 | E11: 0
A12: Apprentices/Trainees | B12: 0 | C12: 0 | D12: 0 | E12: 0
A13: Male Workers | B13: 0 | C13: 0 | D13: 0 | E13: 0
A14: Female Workers | B14: 0 | C14: 0 | D14: 0 | E14: 0
A15: TOTAL | B15: =SUM(B9:B14) -> 0 | C15: =SUM(C9:C14) -> 0 | D15: =SUM(D9:D14) -> 0 | E15: =SUM(E9:E14) -> 0
A17: B. WELFARE FACILITIES
A18: Facility | B18: Available (Y/N) | C18: No./Capacity | D18: Condition | E18: Observation | F18: Action Required
A19: Canteen | B19: Yes | D19: Satisfactory
A20: Drinking Water | B20: Yes | D20: Satisfactory
A21: Washing Facility | B21: Yes | D21: Satisfactory
A22: Rest/Shelter Room | B22: Yes | D22: Satisfactory
A23: First-Aid Boxes | B23: Yes | D23: Satisfactory
A24: Medical Facility | B24: Yes | D24: Satisfactory
A25: Ambulance/Transport | B25: Yes | D25: Satisfactory
A26: Toilets | B26: Yes | D26: Satisfactory
A27: Changing Room | B27: Yes | D27: Satisfactory
A28: Creche (if applicable) | B28: Yes | D28: Satisfactory
A30: C. HEALTH & MEDICAL
A31: Particular | B31: Count | C31: Remarks
A32: Medical cases attended | B32: 0
A33: First-aid cases | B33: 0
A34: Hospitalisation cases | B34: 0
A35: Medical examination conducted | B35: 0
A36: Health camps conducted | B36: 0
A37: Occupational health cases | B37: 0
A38: Ambulance cases | B38: 0
A39: ESIC cases | B39: 0
A41: D. ACCIDENT STATEMENT
A42: Particular | B42: No. of Cases | C42: Man-days Lost
A43: Fatal Accident | B43: 0 | C43: 0
A44: Major Accident | B44: 0 | C44: 0
A45: Minor Accident | B45: 0 | C45: 0
...

Sheet Mar
A1: WELFARE OFFICER RETURN – Mar 2026-27
A3: Factory Name | D3: Factory Licence No.
A4: Address | D4: Reporting Period | E4: Mar 2026-27
A5: Welfare Officer | D5: Total Workers | E5: =E15 -> 0
A7: A. MANPOWER STATEMENT
A8: Category | B8: Opening | C8: Joining | D8: Separation | E8: Closing
A9: Permanent Workers | B9: 0 | C9: 0 | D9: 0 | E9: 0
A10: Contract Workers | B10: 0 | C10: 0 | D10: 0 | E10: 0
A11: Temporary Workers | B11: 0 | C11: 0 | D11: 0 | E11: 0
A12: Apprentices/Trainees | B12: 0 | C12: 0 | D12: 0 | E12: 0
A13: Male Workers | B13: 0 | C13: 0 | D13: 0 | E13: 0
A14: Female Workers | B14: 0 | C14: 0 | D14: 0 | E14: 0
A15: TOTAL | B15: =SUM(B9:B14) -> 0 | C15: =SUM(C9:C14) -> 0 | D15: =SUM(D9:D14) -> 0 | E15: =SUM(E9:E14) -> 0
A17: B. WELFARE FACILITIES
A18: Facility | B18: Available (Y/N) | C18: No./Capacity | D18: Condition | E18: Observation | F18: Action Required
A19: Canteen | B19: Yes | D19: Satisfactory
A20: Drinking Water | B20: Yes | D20: Satisfactory
A21: Washing Facility | B21: Yes | D21: Satisfactory
A22: Rest/Shelter Room | B22: Yes | D22: Satisfactory
A23: First-Aid Boxes | B23: Yes | D23: Satisfactory
A24: Medical Facility | B24: Yes | D24: Satisfactory
A25: Ambulance/Transport | B25: Yes | D25: Satisfactory
A26: Toilets | B26: Yes | D26: Satisfactory
A27: Changing Room | B27: Yes | D27: Satisfactory
A28: Creche (if applicable) | B28: Yes | D28: Satisfactory
A30: C. HEALTH & MEDICAL
A31: Particular | B31: Count | C31: Remarks
A32: Medical cases attended | B32: 0
A33: First-aid cases | B33: 0
A34: Hospitalisation cases | B34: 0
A35: Medical examination conducted | B35: 0
A36: Health camps conducted | B36: 0
A37: Occupational health cases | B37: 0
A38: Ambulance cases | B38: 0
A39: ESIC cases | B39: 0
A41: D. ACCIDENT STATEMENT
A42: Particular | B42: No. of Cases | C42: Man-days Lost
A43: Fatal Accident | B43: 0 | C43: 0
A44: Major Accident | B44: 0 | C44: 0
A45: Minor Accident | B45: 0 | C45: 0
...
